---
layout: post
title: "[Python] 예외처리"
category: [Python]

---
<br>

`예외처리`에 대해 알아보자
<!-- more -->

<hr>



# 예외처리
---
```
try:
    ...
except [발생 오류[as 오류 메세지변수]]]:
    ...
```

즉 다음과 같이 3가지 형태로 사용할 수 있다.
1. Try, except만 사용하는 경우
```
try:
    ...
except:
    ...
```
이 경우 오류 종류에 상관없이 오류가 발생하면 except 블록을 수행한다.  

2. 발생 오류만 포함한 except
```
try:
    ...
except 발생 오류:
    ...
```
이 경우 오류 발생했을 때 except문에 미리 정해 놓은 오류 이름과 일치할 때만 except 블록을 수행한다.

3. 발생 오류와 오류 메시지 변수까지 포함한 except
```
try:
    ...
except 발생 오류 as 오류 메세지 변수:
    ...
```
이 경우 2번과 마찬가지로 오류 발생했을 때 except문에 미리 정해 놓은 오류 이름과 일치할 때만 except 블록을 수행하며 오류 메시지 내용까지 알고자 할때 사용한다.

## try .. finally
---
finally절은 try문 수행 도중 예외 발생 여부에 상관없이 항상 수행된다. 보통 finally절은 사용한 리소스를 close 해야할 때 많이 사용한다.
```python
f = open('open.txt', 'w')
try:
    # 수행
finally:
    f.close()
```

<!--try.py-->
```python
try:
    a = [1,2]
    print(a[3])
    4/0
except IndexError:
    print("인덱싱 할 수 없습니다.")
except ZeroDivisionError:
    print("0으로 나눌 수 없습니다.")
```
```
python>python try.py
인덱싱 할 수 없습니다.
```
인덱싱 오류가 먼저 발생했으므로 ZeroDivisionError 오류는 발생하지 않았다.  

<!--try.py-->
```python
try:
    a = [1,2]
    print(a[0])
    4/0
except IndexError as e:
    print("인덱싱 할 수 없습니다.")
    print(e)
except ZeroDivisionError as e:
    print("0으로 나눌 수 없습니다.")
    print(e)
```
```
D:\기타\python>python try.py
1
0으로 나눌 수 없습니다.
division by zero
```

<!--try.py-->
```python
try:
    a = [1,2]
    print(a[3])
    4/0
except (IndexError, ZeroDivisionError) as e:
    print(e)
```
```
D:\기타\python>python try.py
list index out of range
```

## 오류 회피
---
<!--try.py-->
```python
try:
    a = [1,2]
    print(a[3])
except IndexError as e:
    pass
```
```
D:\기타\python>python try.py
```

## 오류 발생시키기
---
<!--try.py-->
```python
class Bird:
    def fly(self):
        raise NotImplementedError

class Eagle(Bird):
    pass

eagle = Eagle()
eagle.fly()
```
```python
D:\기타\python>python try.py
Traceback (most recent call last):
  File "try.py", line 10, in <module>
    eagle.fly()
  File "try.py", line 3, in fly
    raise NotImplementedError
NotImplementedError
```
Bird 클래스를 상속받는 자식 클래스는 반드시 fly 함수를 구현해야 한다고 할 때 사용(즉 부모인 Bird 클래스의 fly 함수가 실행되면 에러)

<!--try.py-->
```python
class Bird:
    def fly(self):
        raise NotImplementedError


class Eagle(Bird):
    def fly(self):
        print("good")

eagle = Eagle()
eagle.fly()
```
```
D:\기타\python>python try.py
good
```

## 예외만들기
---
오류 클래스를 만들 때 `Exception` 오류 클래스를 상속해야 한다.
<!--try.py-->
```python
class MyErr(Exception):
    pass

def say(nick):
    if nick == '바보':
        raise MyErr()
    print(nick)

try:
    say('멍청이')
    say('바보')
except MyErr:
    print("에러 검출")
```
```
D:\기타\python>python try.py
멍청이
에러 검출
```
오류 메시지를 사용하고 싶다면 다음과 같이 예외 처리를 하면 된다.
```python
class MyErr(Exception):
    pass

def say(nick):
    if nick == '바보':
        raise MyErr()
    print(nick)

try:
    say('멍청이')
    say('바보')
except MyErr as e:
    print(e)
```
```
D:\기타\python>python try.py
멍청이

```
하지만 결과를 보면 오류 메시지가 정상적으로 출력되지 않음을 알 수 있다. 오류 메시지를 정상적으로 보이게 하려면 오류 클래스에
다음과 같이 `__str__` 메서드가 구현되어 있어야 한다. `__str__` 메서드는 오류 메시지를 print 문으로 출력할 경우에 호출되는 메서드이다.
<!--try.py-->
```python
class MyErr(Exception):
    def __str__(self):
        return "에러 검출"


def say(nick):
    if nick == '바보':
        raise MyErr()
    print(nick)

try:
    say('멍청이')
    say('바보')
except MyErr as e:
    print(e)
```
```
D:\기타\python>python try.py
멍청이
에러 검출
```
정상적으로 오류 메시지가 출력되는 것을 확인할 수 있다.

